Workbook
Name bcd_scrap_hs7602: Inputs!$B$8
Name sws_rate_on_bcd: Inputs!$B$9
Name igst_rate_hs7602: Inputs!$B$10
Name insurance_rate: Inputs!$B$11
Name insured_value_uplift: Inputs!$B$12
Name igst_credit_lag_days: Inputs!$B$13
Name igst_itc_available: Inputs!$B$14
Name psic_cost_usd_per_box: Inputs!$B$15
Name heavies_net_value_frac_of_lme_al: Inputs!$B$16
Name domestic_anchor_premium_inr_t: Inputs!$B$17
Name conversion_cost_inr_t: Inputs!$B$18
Name margin_threshold_inr_t: Inputs!$B$19
Name bcd_primary_al_hs7601: Inputs!$B$20
Name mcx_domestic_premium_inr_kg: Inputs!$B$21
Name customs_fx_markup_frac: Inputs!$B$22
Name customs_fx_notification_validity_days: Inputs!$B$23
Name mcx_al_lot_mt: Inputs!$B$24
Name mcx_al_margin_used_frac: Inputs!$B$25
Name fx_forward_bank_margin_inr: Inputs!$B$26
Name mcx_roll_days_before_expiry: Inputs!$B$27
Name lme_cash_prompt_bdays: Inputs!$B$28
Name mcx_al_tick_inr_kg: Inputs!$B$29
Name demurrage_usd_per_box_day: Inputs!$B$30
Name param_keys: Inputs!$A$8:$A$63
Name param_values: Inputs!$B$8:$B$63
Name pdates_grade_factor_zorba: Inputs!$A$70:$A$79
Name pvals_grade_factor_zorba: Inputs!$B$70:$B$79
Name pdates_grade_factor_taint_tabor: Inputs!$A$83:$A$92
Name pvals_grade_factor_taint_tabor: Inputs!$B$83:$B$92
Name pdates_grade_factor_tense: Inputs!$A$96:$A$105
Name pvals_grade_factor_tense: Inputs!$B$96:$B$105
Name pdates_grade_factor_mix_pit: Inputs!$A$109:$A$118
Name pvals_grade_factor_mix_pit: Inputs!$B$109:$B$118
Name pdates_wc_rate_inr_pa: Inputs!$A$122:$A$130
Name pvals_wc_rate_inr_pa: Inputs!$B$122:$B$130
Name pdates_customs_usdinr_import: Inputs!$A$134:$A$148
Name pvals_customs_usdinr_import: Inputs!$B$134:$B$148
Name customs_fx_first: Inputs!$A$134
Name customs_fx_last: Inputs!$A$148
Name window_start: Inputs!$B$153
Name window_end: Inputs!$B$154
Name horizon_end: Inputs!$B$155
Name conv_step_5a: Inputs!$B$156
Name grid_tonnes_mt: Inputs!$B$157
Name day_count_inr: Inputs!$B$158
Name day_count_usd: Inputs!$B$159
Name kg_per_mt: Inputs!$B$160
Name tol_parity_inr_t: Inputs!$B$161
Name tol_trade_inr: Inputs!$B$162
Name tol_grid_inr: Inputs!$B$163
Name tol_cashflow_inr: Inputs!$B$164
Name tol_mcx_inr: Inputs!$B$165
Name tol_usd_t: Inputs!$B$166
Name mcx_slippage_ticks: Inputs!$B$173
Name mcx_txn_cost_frac: Inputs!$B$174
Name lc_sight_payment_lag_days: Inputs!$B$175
Name lc_presentation_period_days: Inputs!$B$176
Name boe_lag_days: Inputs!$B$177
Name survey_lag_days: Inputs!$B$178
Name provisional_invoice_frac: Inputs!$B$179

Sheet README
A1: ACADEMIC SIMULATION — not actual trades
A2: Meridian Non-Ferrous Trading Pvt Ltd (SIM) — Aluminium Scrap Desk, Mumbai
A3: ACADEMIC SIMULATION — not actual trades. Master workbook, formula-driven for Components 1–3. Backtest window 2022-03-01 → 2022-08-31; engine horizon 2022-10-31.
A5: How to read a cell — the colour convention
A7: colour | B7: meaning
A8: blue | B8: An input you may change: a register parameter, a ticket field, a market print. Everything downstream re-computes.
A9: black | B9: An Excel formula. Never typed — derived from blue cells and other formulas.
A10: green | B10: A value produced by the Python engine and pasted here. Two kinds, and the sheets say which: *check* columns that nothing depends on, and *carried* columns (a leg amount out of the ticket lifecycle) that a formula then converts and aggregates. `value_src` / `amount_src` name them row by row.
A11: dark grey | B11: A row key or a label — a date, an id, a provenance flag, a source string.
A14: Provenance — CONTRACTS §1.2. Every input on every sheet carries one of these flags
A16: flag | B16: meaning
A17: DIRECT | B17: Observed from a named public source. Here: LME cash / 3M / spread / stock (Westmetall, which republishes LME official prices); the RBI and Fed policy-rate step paths; BCD, SWS and IGST on HS 7602 and the CBIC notified import rate; MCX contract specifications.
A18: PROXY | B18: A real observable standing in for the thing we need, or a transformation of real data. Here: USD/INR (the ECB EUR/INR ÷ EUR/USD cross, standing in for the RBI/FBIL reference rate — PENDING a measured comparison); the 3-month rates and the covered-interest-parity forwards; the MCX panel series, which is duty-paid import parity and therefore has **zero cross-exchange basis by construction**; the Drewry WCI freight shape.
A19: ASSUMPTION | B19: A judgement, with a justification in the register. Here: the freight *levels* and the lag-2 grade mix (both hindsight reconstructions); container payloads; port and conversion costs; the domestic anchor premium; the working-capital rate; every Phase 3 book parameter still served from code.
A20: SIM | B20: Simulated. Every counterparty, vessel, voyage, forwarder, bank, survey outcome, dwell day and payment delay in this workbook is fictional and its name ends "(SIM)".
A23: Sheet map
A25: sheet | B25: part | C25: rows | D25: formula_cells | E25: formula_share | F25: what it is
A26: README | B26: this page | D26: 0 | E26: 0% | F26: Sheet map, colour and provenance legends, how to use the workbook in an interview.
A27: Inputs | B27: register | D27: 0 | E27: 0% | F27: Every parameter Components 1–3 read, with unit, flag, source and verification status. Scalars carry named ranges; dated parameters are the register's own breakpoints and are resolved by formula. Change a blue cell here and the whole workbook moves.
A28: Market_Daily | B28: panel | C28: 251 | D28: 2761 | E28: 32% | F28: One row per LME trading day, 2022-01-03 → 2022-12-30: LME cash/3M/spread/stock, USD/INR and the 3-month rates, the MCX slots and their expiries, freight per lane. Four derived columns are formulas — contract months, the dated parameters resolved on the day, and the MCX parity price with its basis.
A29: Market_Weekly | B29: panel | C29: 43 | D29: 817 | E29: 84% | F29: The CONTRACTS §3 weekly view (W-FRI, valued on the week's last panel day). Every cell is an INDEX/MATCH into Market_Daily.
A30: Parity | B30: Component 1 | C30: 258 | D30: 14706 | E30: 92% | F30: CONTRACTS §5 per MT of scrap, line by line, for every week × grade × lane, plus the three §5a eligibility flags. No computed value is pasted.
A31: Sensitivity | B31: Component 1 | C31: 450 | D31: 11880 | E31: 79% | F31: The two MASTER_SPEC Table 1.5 grids on 1,000 MT: LME × USD/INR, and freight × import duty under both FOB and CFR terms. Each cell re-derives the whole build-up at the shocked market.
A32: Term_Structure | B32: Component 1 | C32: 53 | D32: 838 | E32: 61% | F32: Table 1.7: Cash–3M weekly, the M+1 pricing basis implied by the curve, the realised M+1 average (labelled HINDSIGHT), and the MCX M1 → M2 roll.
A33: Counterparties | B33: Component 2 | C33: 6 | D33: 0 | E33: 0% | F33: The SIM supplier and buyer register with credit limits and the Phase 5 profile features.
A34: Trade_Book | B34: Component 2 | C34: 62 | D34: 45 | E34: 2% | F34: The nine SPA tickets and the hedge stack. Ticket fields are inputs; the §5a eligibility of each trade is re-tested live against the Parity sheet.
A35: Cashflows | B35: Component 3 | C35: 1382 | D35: 13930 | E35: 38% | F35: The dated cash ledger with its FX conversion derived per settle date, and the MCX margin schedule (variation margin, initial margin, slippage and charges) derived end to end from Market_Daily.
A36: MTM_Daily | B36: Component 3 | C36: 1458 | D36: 9555 | E36: 26% | F36: Leg valuations on the declared marking grid, including the unsold-cargo replacement mark and the FX-forward marks, and per-trade cumulative P&L.
A37: Attribution | B37: Component 3 | C37: 174 | D37: 1044 | E37: 30% | F37: The daily bucket identities recomputed in Excel, lifetime P&L by trade and factor, and the eight-step attribution chain worked live on two legs.
A38: Equity_Curve | B38: Component 3 | C38: 164 | D38: 1034 | E38: 47% | F38: Book cumulative P&L every panel day, assembled by formula, with a native Excel line chart.
A39: Checks | B39: controls | C39: 787 | D39: 4071 | E39: 50% | F39: Every workbook result differenced against the Python engine, with a named tolerance and a PASS flag. Start here.
A42: Five things to do with this workbook in an interview
A44: do this | B44: and it shows
A45: Prove the parity is live | B45: Inputs → change `bcd_scrap_hs7602` from 0.025 to 0.05. Watch Parity `bcd_inr_t`, `landed_inr_t` and `net_arb_inr_t` move on all 258 rows, `trade_eligible` flip on the marginal weeks, and Trade_Book `parity_eligible_live` follow. Then undo it — Checks will go red until you do, which is the point.
A46: Prove the P&L is live | B46: Market_Daily → change a `usdinr` print. Cashflows re-converts every USD flow settling that day, MTM_Daily re-prices the replacement mark and the FX forwards, and the Equity_Curve chart redraws.
A47: Show the hedge is not a fake | B47: Attribution §3a: the short MCX hedge on the day the LME broke from its all-time high. (a) is the whole move, (b) the cross-exchange basis is **zero**, (e) is small and negative because a short MCX position is short USD, and (g) is the carry. §3b shows a USD payable and its forward cancelling in (e) and (g).
A48: Show the discipline | B48: Trade_Book `parity_eligible_live` vs `book_trade_eligible`: each ticket is re-tested against the CONTRACTS §5a rule that was declared before any Phase 1 result existed.
A49: Show the honesty | B49: Checks → the scoreboard, then Inputs §4: the Phase 3 parameters still served from code rather than from the register, listed with their flags.
A52: What is NOT in this workbook, and why
A54: left in Python | B54: why
...

Sheet Inputs
A1: ACADEMIC SIMULATION — not actual trades
A2: Inputs — assumptions register (config/params/*.yaml) and workbook constants
A3: blue = input you may change · black = formula · green = pasted Python output (checks only). Flags: DIRECT = observed from a named public source, PROXY = a real observable standing in, ASSUMPTION = a judgement.
A5: 1. Scalar parameters — change a blue value and every sheet that uses it moves
A7: key | B7: value | C7: unit | D7: flag | E7: named_range | F7: file | G7: source | H7: verify | I7: note
A8: bcd_scrap_hs7602 | B8: 0.025 | C8: frac_of_assessable_value | D8: DIRECT | E8: bcd_scrap_hs7602 | F8: regulatory.yaml | G8: Notification No. 50/2017-Customs dated 30-Jun-2017 (effective-rate notification), Table S.No. 385: chapter/heading '7602', description 'Aluminium scrap', standard rate '2.5%' (CBIC portal id 1002538; cached data/raw/regulatory/cbic_notifications/cs50-2017_principal.pdf). Budget amendments to 50/2017 checked for any change to S.No. 385 / 7602: 06/2018, 25/2019, 01/2020, 02/2021, 55/2021 (HSN-2022 alignment), 02/2022, 02/2023 — none touches it (cached in the same folder). | H8: VERIFIED 2026-09-16 (rate in principal notification + no change in the Budget/HSN amendment notifications read). Residual gap: ~40 non-Budget amendments to 50/2017 (2017–2022) were listed but not individually opened; pages read on 2026-09-16 (The Tribune/ANI 08-Jul-2026 on the AAI representation, https://www.tribuneindia.com/news/aluminium-quality/aluminium-association-of-india-urges-centre-to-notify-bis-standards-for-aluminium-scrap, cached data/raw/regulatory/news/tribune_aai_urges_bis_standards_aluminium_scrap.html; AlCircle Apr-2026) still cite 2.5% BCD on aluminium scrap, so an interim change and reversal is very unlikely. | I8: The seed's claim that 'Budget 2021-22 cut BCD on aluminium scrap to 2.5%' was WRONG — Budget 2021-22 cut copper scrap (7404) to 2.5%; aluminium scrap has been at 2.5% since at least the June-2017 GST-era re-issue of the effective-rate notification. Applies to both 7602 00 10 (ISRI-coded scrap) and 7602 00 90 (other) because S.No. 385 is written at heading level. The 5-percentage-point gap to primary aluminium (bcd_primary_al_hs7601 = 7.5%) is the policy wedge that makes scrap-to-ingot conversion in India an arbitrage (see notes §1).
A9: sws_rate_on_bcd | B9: 0.1 | C9: frac_of_bcd | D9: DIRECT | E9: sws_rate_on_bcd | F9: regulatory.yaml | G9: Finance Act 2018 s.110(3): SWS 'at the rate of ten per cent' on the aggregate of duties, taxes and cesses levied under s.12 Customs Act, excluding safeguard/CVD/anti-dumping duty and SWS itself (text read at https://indiankanoon.org/doc/20129988/). IGST and GST compensation cess are exempted from SWS by Notification 13/2018-Customs (portal title read, truncated after 'from the whole o…'; text not opened). Exemption list Notification 11/2018-Customs (cached cs11-2018_sws_exempt.pdf) and its 2020/2021/2022 amendments 09/2020, 14/2021, 03/2022, 24/2022 contain no chapter-76 entry. | H9: VERIFIED 2026-09-16 (statute text + exemption notifications read; no aluminium scrap exemption). Not re-checked: amendments to 11/2018 issued outside Budget days. | I9: With BCD 2.5% and no AIDC, SWS = 0.25% of assessable value, so BCD + SWS = 2.75% of AV on scrap versus 8.25% on primary aluminium.
A10: igst_rate_hs7602 | B10: 0.18 | C10: frac_of_av_plus_customs_duty | D10: DIRECT | E10: igst_rate_hs7602 | F10: regulatory.yaml | G10: Notification No. 1/2017-Integrated Tax (Rate) dated 28-Jun-2017, Schedule III (18%), S.No. 263: '7602 Aluminium waste and scrap' (CBIC portal id 1001202; cached igst01-2017_rate.pdf). Amendments 14/2021-IT(R) (w.e.f. 01-Jan-2022) and 01/2022-IT(R) (31-Mar-2022) read — neither touches S.No. 263. | H10: VERIFIED 2026-09-16 (principal schedule + the two amendments in force around the window). | I10: IGST base = AV + BCD + SWS (Customs Tariff Act s.3 — IGST charged on value plus customs duties; subsection text not re-fetched). Primary aluminium 7601 is in the same Schedule III (S.No. 262), so IGST is neutral between the scrap and primary routes.
A11: insurance_rate | B11: 0.001 | C11: frac_of_insured_value | D11: ASSUMPTION | E11: insurance_rate | F11: logistics.yaml | G11: Desk assumption: marine cargo open-cover premium for non-ferrous scrap, ICC (A)/(B) clauses | H11: PENDING — obtain an indicative 2022 marine cargo rate for metal scrap from an Indian insurer's published tariff guidance or a broker note | I11: 0.10% of insured value per shipment; plausible range 0.05%-0.20% (scrap is low-theft but prone to wetting/contamination claims). Immaterial to parity (~USD 2-3/MT). NOTE for the regulatory owner (not verified here): for customs assessable value, the Customs Valuation Rules 2007 (Rule 10(2)) deem insurance at 1.125% of FOB when the actual cost is not ascertainable — a customs-valuation rule, distinct from this commercial premium.
A12: insured_value_uplift | B12: 1.1 | C12: multiple_of_cif_value | D12: DIRECT | E12: insured_value_uplift | F12: logistics.yaml | G12: ICC Uniform Customs and Practice for Documentary Credits (UCP 600), Article 28(f)(ii): if the credit is silent, insurance cover must be at least 110% of the CIF or CIP value | H12: PARTIAL 2026-09-16 — wording confirmed via secondary reproduction (tradefinance.training 'UCP comparison Part 4'); the ICC publication itself is paywalled | I12: Market convention for LC-financed imports; insurance_usd_t = insurance_rate x 1.10 x CFR value per CONTRACTS §5 (CFR = FOB + freight; the grade factor is quoted on a CFR India basis).
A13: igst_credit_lag_days | B13: 45 | C13: days | D13: ASSUMPTION | E13: igst_credit_lag_days | F13: regulatory.yaml | G13: Desk construction: IGST is paid with the Bill of Entry (~1 day after arrival) and recovered as input tax credit when the GSTR-3B for the month of the domestic sale is filed (20th of the following month); for a sale ~10 days after arrival that is ~40–50 days | H13: N/A — cash-cycle assumption (GSTR-3B due date rule stated from CGST Rules r.61, not re-fetched) | I13: Used ONLY for the IGST financing line in CONTRACTS §5 (igst_finance_inr_t); IGST itself is not a landed cost while igst_itc_available is true. At 18% × ~INR 2.3 lakh × 45/365 × 9.5–10% ≈ INR 500/t.
A14: igst_itc_available | B14: TRUE | C14: bool | D14: ASSUMPTION | E14: igst_itc_available | F14: regulatory.yaml | G14: Desk assumption: GST-registered importer re-selling taxable goods claims full ITC on IGST paid on the Bill of Entry | H14: N/A — structural assumption (legal basis: Bill of Entry is an ITC document under CGST Rules r.36(1)(d); rule text not re-fetched) | I14: When true, import IGST is excluded from landed cost; only its financing from the Bill of Entry to the GSTR-3B offset is kept (igst_credit_lag_days, CONTRACTS §5 igst_finance_inr_t). Real-world caveat: ITC is cash-neutral only after the output invoice; a desk with thin domestic output tax liability can carry a blocked-credit balance — that is a working-capital cost, not a P&L cost.
A15: psic_cost_usd_per_box | B15: 40 | C15: usd_per_box | D15: ASSUMPTION | E15: psic_cost_usd_per_box | F15: regulatory.yaml | G15: Desk assumption — no 2022 PSIA tariff was retrieved | H15: PENDING — obtain an inspection-agency (PSIA) 2022 quote or published fee for radiation + explosives inspection of a 20ft scrap container at Jebel Ali | I15: ≈ USD 1.6/MT at 25 MT/box — small but now included in CONTRACTS §5 port charges for non-safe origins (JEA_NSA), per review; material to operations (lead time ~2–4 days before stuffing/sailing).
A16: heavies_net_value_frac_of_lme_al | B16: 0.8 | C16: frac_of_lme_3m_usd_t_per_mt_of_heavies | D16: ASSUMPTION | E16: heavies_net_value_frac_of_lme_al | F16: scrap_grades.yaml | G16: Desk judgement: a mixed Zorba heavies concentrate (copper, brass, zinc, stainless) sells well above aluminium per tonne; valuing it at LME aluminium 3M and deducting ~20% for separation, handling and a buyer's margin is deliberately conservative | H16: PENDING — no public 2022 or 2024 India price for Zorba heavies / 'Zebra' was retrieved. Next step: a BigMint or Fastmarkets heavy non-ferrous shred price series, or a US ReMA 'Zebra' quote converted to CFR India. | I16: At window-average LME 3M ≈ USD 2,850/t and 0.05 heavies this credit is ≈ USD 114/t ≈ INR 8,900/t of scrap — ignoring it (previous register) was a ₹9k/t omission, larger than the margin hurdle. P1 sensitivity: 0.4–1.5.
A17: domestic_anchor_premium_inr_t | B17: -9000 | C17: inr_per_mt | D17: ASSUMPTION | E17: domestic_anchor_premium_inr_t | F17: commercial.yaml | G17: Median of 15 dated BigMint ADC12 ex-Delhi prices (01-Dec-2023 → 11-Dec-2025, republished by AlCircle; OEM-approved prints moved to a non-OEM basis by the INR 8,000 OEM − non-OEM gap in the 05/11-Dec-2024 articles) minus duty-paid LME CASH parity on the day before publication: LME cash (Westmetall) × ECB USD/INR × (1 + 7.5% × 1.10). Median −8,955 → −9,000; mean −16,422; range −52,068 … +12,861 (data/interim/price_evidence/adc12_vs_duty_paid_parity.csv, exact sentences in desk/data/fetch_price_evidence.py). | H17: PENDING — no 2022 ADC12/LM6 India price series was retrievable (AlCircle/BigMint 2022 archives not found in public). Next step: weekly 2022 ADC12 ex-Delhi/Chennai from BigMint or an automaker's 2022 monthly alloy settlement prices, compared with MCX near-month. | I17: REVIEW FIXES. (1) Basis: recalibrated against duty-paid LME CASH parity — the basis of the panel's MCX proxy that CONTRACTS §5 adds this premium to — instead of 3M (cash–3M basis in the sample: median INR ~4,100/t; M1 carry adds a further 0–1,300/t, not modelled). (2) Evidence: the previous −18,000 was the mean of two points computed with the articles' own LME figures (the 24-Feb-2024 point used 3M $2,247; Westmetall 3M on 23-Feb-2024 was $2,197). (3) Regime dependence is strong: correlation of the premium with parity −0.93; OLS short-run pass-through of parity into ADC12 = 0.15 (domestic_anchor_passthrough_frac). Premiums were +5k…+13k at parity ~191–205k (H1-2024) and −34k…−52k at parity ~235–276k (late 2024–25). The 2022 window's parity ran ~200–330k, so a constant premium overstates the anchor at the March spike and understates it in July–August. P1 must publish window_open as a band over domestic_anchor_premium_sensitivity_inr_t and under the sticky variant (domestic_anchor_trailing_bdays), not as a single flag. (4) CRISIL (Sept 2021, cached CMR PDF) says 'Secondary aluminium continues to be 25-30% cheaper than primary aluminium' with no date, product or price basis; against the dated 2023–25 ADC12 prints (−20% … +7% of parity) it reads as a cost or low-grade-product statement and is kept only as the low-end sensitivity (−55,000 ≈ 25% of the window-mean MCX proxy of INR ~222k/t), not rejected and not used as the base.
A18: conversion_cost_inr_t | B18: 12000 | C18: inr_per_mt_ingot | D18: ASSUMPTION | E18: conversion_cost_inr_t | F18: commercial.yaml | G18: Desk toll-conversion charge per tonne of secondary alloy INGOT produced (fuel, power, flux/salt, alloying top-up, labour, dross handling, overheads and the converter's margin), triangulated from BigMint/AlCircle 24-Feb-2024 (https://www.alcircle.com/news/raw-material-costs-propel-india-s-aluminium-adc12-prices-upward-w-o-w-108017): ADC12 INR 204,000/t vs domestic Tense INR 172,500/t ex-Delhi; 1 t of ingot needs ~1/0.90 = 1.11 t of Tense (INR 191,700), leaving INR ~12,300/t of ingot; the Dec-2024 non-OEM / OEM prints (INR 201,000 / 209,000) give ~INR 9,000–17,000/t of ingot. Range INR 8,000–18,000 per t of INGOT. | H18: PENDING — no 2022 Indian secondary-smelter cost disclosure retrieved. Next step: cost-of-production note in a listed Indian secondary aluminium producer's 2022 annual report/DRHP (power + fuel + consumables per tonne). | I18: UNIT FIX (review): the evidence is per tonne of ingot, so the unit is inr_per_mt_ingot and CONTRACTS §5 converts it per MT of scrap as conversion_inr_t = conversion_cost_inr_t × recovery_frac_g (e.g. INR 10,760/t of Tense scrap at 0.897 recovery; lower for Zorba, which yields less ingot per tonne). Uniform across grades by design: (i) Zorba's heavies separation cost is netted inside heavies_net_value_frac_of_lme_al; (ii) Taint/Tabor's silicon top-up to ADC12 chemistry costs roughly nothing net, because silicon 553 (~USD 2,030/t CIF Mundra in the same 24-Feb-2024 article) was priced below the alloy it becomes part of; (iii) melt-shop differences are inside the 8–18k range. Cross-check with [CRISIL] (Sept 2021): scrap = 80–85% of total cost incl. taxes and duties, i.e. a 15–20% non-scrap cost base (~INR 30–40k/t of ingot, part non-cash: depreciation, finance, selling) — a broader base than a toll charge; P1 runs it as the upper sensitivity (conversion_cost_sensitivity_inr_t_ingot).
A19: margin_threshold_inr_t | B19: 5000 | C19: inr_per_mt_scrap | D19: ASSUMPTION | E19: margin_threshold_inr_t | F19: commercial.yaml | G19: Desk hurdle: minimum expected net margin per MT of scrap before a trade is allowed (Table 3 row 1.4) | H19: N/A — risk-policy assumption | I19: ≈ 2% of a ~INR 2.3 lakh/MT landed cost. Sized to cover: expected quality/weight claims under the SPA penalty schedule (~0.5–1% of value ≈ INR 1,200–2,300), residual MCX hedge noise over a ~6-week cash cycle (the anchor premium is unhedgeable, see domestic_anchor_premium_inr_t), a few days' demurrage on 25 MT boxes, and leaves ~INR 1,500–2,000 as return on risk capital. Opening a window below this is 'picking up pennies in front of a steamroller' given the LME daily moves of 4–12% seen in Mar-2022.
A20: bcd_primary_al_hs7601 | B20: 0.075 | C20: frac_of_assessable_value | D20: DIRECT | E20: bcd_primary_al_hs7601 | F20: regulatory.yaml | G20: Customs Tariff Act 1975, First Schedule tariff rate for heading 7601 = 7.5% (search summaries attribute the 5% -> 7.5% increase to Budget 2016-17; no Budget-2016 document was retrieved). Notification 50/2017-Customs (principal, cached) has no 7601 concession, and the 2018–2023 Budget amendments read (see bcd_scrap_hs7602) contain no 7601 entry, so the tariff rate applied in 2022. AlCircle (Apr-2026, https://www.alcircle.com/news/can-india-sustain-8-25-aluminium-duties-when-55-of-demand-is-imported-118251, read 2026-09-16): 'Primary aluminium under HS 7601 is charged at 8.25 per cent, scrap under HS 7602 at 2.5 per cent' (8.25% = 7.5% BCD × 1.10 SWS). | H20: PARTIAL 2026-09-16 — chain of evidence is consistent but the 2022 First Schedule page for chapter 76 itself was not retrieved. Next step: download the Customs Tariff chapter 76 as amended by the Finance Act 2022 (CBIC Tax Information Portal > Acts > Customs Tariff Act) and read tariff items 7601 10 10–7601 20 90. | I20: Used only for the MCX import-parity proxy (MCX Aluminium is priced duty-paid; market_proxy.yaml calibrates mcx_domestic_premium_inr_kg on this rate).
A21: mcx_domestic_premium_inr_kg | B21: 0 | C21: inr_per_kg | D21: PROXY | E21: mcx_domestic_premium_inr_kg | F21: market_proxy.yaml | G21: Calibrated in-repo against observed MCX Aluminium nearest-contract closes from a third-party mirror (https://commoditieschart.net/metals/aluminium/mcx-aluminium-futures-prices, retrieved 2026-09-16, cached in data/raw/mcx_thirdparty/commoditieschart_mcx_aluminium_nearest_raw.html via desk.data.fetch_mcx_mirror): implied premium = observed M1 / carry − duty-paid LME cash parity (BCD 7.5% × (1 + SWS 10%)), Mar–Aug 2022, n = 125 common days: mean −0.33, median +1.46, std 6.27 ₹/kg (full 2018–2022: mean −1.03, median −0.02, std 7.71). | H21: PARTIAL — mirror data could not be checked against MCX's own bhavcopy (mcxindia.com returned Akamai HTTP 403 to every request on 2026-09-16). Next step: download MCX bhavcopy for 5 window dates (e.g. 07-Mar, 13-Apr, 16-Jun, 14-Jul, 31-Aug-2022) from a browser, compare ALUMINIUM near-month closes with the mirror, then recompute. | I21: Set to 0.0 rather than the −0.33 window mean because the mean is small relative to its dispersion, the median has the opposite sign and monthly means swing from −9.9 (Mar 2022, MCX's 23:30 IST close lagging the LME official spike) to +3.5 (Jun 2022). Economically: MCX Aluminium is delivered duty-paid in India, so it should sit at LME × USDINR × (1 + BCD × (1 + SWS)) with no systematic extra premium. The calibration depends on bcd_primary_al_hs7601 and sws_rate_on_bcd (regulatory.yaml); recompute if those change. REGIME BIAS (review): unbiased over the window but not within it — Friday proxy M1 minus mirror M1 is +5 to +11 INR/kg on every March-2022 Friday (proxy too high in the LME spike; MCX's evening close lagged the LME official) and mostly −1 to −8 INR/kg on May–July Fridays (−7.52 on 13-May; proxy too low in the trough). Because the parity anchor is built on this proxy, it widens the open/closed swing between the spike and the trough. P1 should run the anchor on the mirror M1 as a sensitivity (still PROXY: third-party, unverified provenance) until MCX bhavcopy closes for 5 window dates are obtained.
A22: customs_fx_markup_frac | B22: 0.011 | C22: frac_of_market_usdinr | D22: PROXY | E22: customs_fx_markup_frac | F22: regulatory.yaml | G22: Computed in-repo 2026-09-16: customs_usdinr_import ÷ market USDINR (data/processed/fx_rates_daily.csv usdinr, ECB cross) on the last business day before each notification, 14 notifications 04-Mar-2022 → 16-Sep-2022: mean +1.11% (range +0.78% to +1.36%); versus the average market rate over each notification's validity period: mean +0.68% (range −0.53% to +1.88%). | H22: PARTIAL — the customs side is DIRECT; the market side is the ECB-cross PROXY, not the RBI reference rate. | I22: Use only as a fallback when a date falls outside customs_usdinr_import. Economic reading: the customs import rate is set roughly at market + ~₹0.85 and then frozen for a fortnight, so in a depreciating-INR fortnight (e.g. 22-Jul-2022 validity, +1.88%) duty is computed on a stale-but-high rate, and in a sharp INR fall (e.g. 06-May, 16-Sep validity) the importer briefly pays duty on a rate BELOW market.
A23: customs_fx_notification_validity_days | B23: 14 | C23: calendar_days | D23: ASSUMPTION | E23: customs_fx_notification_validity_days | F23: parity.yaml | G23: CBIC fortnightly exchange-rate notifications: consecutive USD-changing breakpoints in customs_usdinr_import (regulatory.yaml) are 14–21 days apart | H23: N/A — coverage rule for dates outside the registered notifications | I23: The registered notification path runs 18-Feb-2022 → 16-Sep-2022. A parity week whose value date is before the first notification, or more than this many days after the last one, uses customs_fx_markup_frac × market USD/INR (the register's documented fallback) instead of clamping a stale notified rate; parity_weekly.csv labels each row in customs_fx_src. Only out-of-window context weeks (Jan–mid-Feb and October 2022) are affected.
A24: mcx_al_lot_mt | B24: 5 | C24: mt_per_lot | D24: DIRECT | E24: mcx_al_lot_mt | F24: exchange.yaml | G24: [C385] and [C617] Annexure 1: 'Trading Unit 5 MT' | H24: VERIFIED 2026-09-16 (identical in Jun-2021 and Oct-2022 circulars) | I24: Hedge tonnage is rounded to whole lots via desk.units.mt_to_lots; 1,000 MT scrap ≈ 0.8–0.9 × 1,000 MT metal ≈ 160–180 lots.
A25: mcx_al_margin_used_frac | B25: 0.1 | C25: frac_of_contract_value | D25: ASSUMPTION | E25: mcx_al_margin_used_frac | F25: exchange.yaml | G25: Desk assumption = initial margin minimum 8% + ELM 1% + ~1% SPAN/volatility cushion | H25: PENDING — replace with MCXCCL daily SPAN aluminium margin % for Mar–Aug 2022 if the risk-parameter archive becomes retrievable | I25: Used for margin & liquidity (Table 6 row 4.5) and variation-margin cash planning; stress with 0.12–0.15 in the crash fortnight.
A26: fx_forward_bank_margin_inr | B26: 0.1 | C26: inr_per_usd | D26: ASSUMPTION | E26: fx_forward_bank_margin_inr | F26: exchange.yaml | G26: Desk assumption for a mid-size corporate importer's forward (spot + premium) margin over the interbank mid | H26: PENDING — no 2022 bank rate card for corporate forward margins was retrieved; check RBI FX-Retail platform documentation / RBI speeches on retail FX spreads for an order of magnitude | I26: 10 paise ≈ 0.13% of notional (≈ ₹230k on a USD 2.3 mn cargo). Range 0.03 (large corporate) to 0.25 (small SME).
... A30: demurrage_usd_per_box_day | B30: 35 | C30: usd_per_box_per_day | D30: ASSUMPTION | E30: demurrage_usd_per_box_day | F30: logistics.yaml | G30: Desk assumption: combined carrier detention + CFS ground rent per box per day beyond detention_free_days (first slab) | H30: PENDING — retrieve 2022 Wayback copies of a carrier's India import detention slabs (USD/day by box size) and a CFS ground-rent tariff (INR/day) | I30: Blended 20ft/40ft first-slab figure; carriers escalate slabs after 5-10 days, so long delays cost more per day. Range 15-75 USD/box/day. Used by P3 attribution factor (f) and the 'BIS-QCO + demurrage' stress.
A31: container_payload_mt_20ft | B31: 25 | C31: mt_per_box | D31: ASSUMPTION | F31: logistics.yaml | G31: MASTER_SPEC_V3 Table 4 row 2.1 ('containerised ~24-26 MT/box'); 20ft dry box max gross 30,480 kg less ~2,200 kg tare | H31: PENDING — confirm typical Zorba / Taint-Tabor 20ft load weights from a Jebel Ali shipper's packing list or a BigMint/Fastmarkets methodology note | I31: BASE payload used to convert freight_weekly.csv USD/box into USD/MT. Heavy scrap cubes out by weight, not volume, so the 20ft box is used ex-Gulf and loaded close to the carrier's weight cap. Midpoint of the spec's 24-26 MT. Grade-specific payloads (container_payload_mt_20ft_<grade>) rescale per-box costs in CONTRACTS §5.
A32: container_payload_mt_40ft | B32: 21 | C32: mt_per_box | D32: ASSUMPTION | F32: logistics.yaml | G32: US federal gross vehicle weight limit 80,000 lb (23 CFR 658.17) applied to typical tractor (~8 t) + 40ft chassis (~3 t) + container tare (~3.8 t) | H32: PENDING — the eCFR page redirected to a bot check when fetched; re-check 23 CFR 658.17 on ecfr.gov and a US scrap exporter's 40ft load weights (Recycling Today / ReMA) | I32: US scrap is exported in 40ft boxes (backhaul equipment availability) but road weight limits, not box capacity, cap the payload at roughly 20-22 MT for non-permitted drayage (36.3 t GVW - ~15.3 t tractor, chassis and box). Range 19-26 MT (26 MT only with port-side transloading / overweight permits). This is why the spec's generic 24-26 MT/box is NOT used for the 40ft lane.
A33: container_payload_mt_20ft_zorba | B33: 26 | C33: mt_per_box | D33: ASSUMPTION | F33: logistics.yaml | G33: Desk judgement: shredded Zorba is dense (loose bulk ~1.0–1.3 t/m³) and loads to the ~27–28 t 20ft payload cap | H33: PENDING — packing lists / bills of lading for Zorba 95/5 20ft shipments (review asked for grade-specific payloads) | I33: CONTRACTS §5 scales per-box freight, port and PSIC costs by container_payload_mt_20ft / this value.
A34: container_payload_mt_20ft_taint_tabor | B34: 20 | C34: mt_per_box | D34: ASSUMPTION | F34: logistics.yaml | G34: Desk judgement: baled old sheet cubes out before the weight cap in a 33 m³ 20ft box (bales ~0.6 t/m³) | H34: PENDING — packing lists for baled Taint/Tabor 20ft shipments | I34: Range 16–23 MT; the lower payload raises per-MT freight and port costs by 25% versus the 25 MT base.
A35: container_payload_mt_20ft_tense | B35: 25 | C35: mt_per_box | D35: ASSUMPTION | F35: logistics.yaml | G35: Desk judgement: loose castings load to near the weight cap, as the base | H35: PENDING — packing lists for Tense 20ft shipments | I35: Equal to the base payload.
A36: container_payload_mt_40ft_zorba | B36: 21 | C36: mt_per_box | D36: ASSUMPTION | F36: logistics.yaml | G36: US road-weight cap binds before volume for dense Zorba (see container_payload_mt_40ft) | H36: PENDING — as container_payload_mt_40ft | I36: Equal to the 40ft base.
A37: container_payload_mt_40ft_taint_tabor | B37: 21 | C37: mt_per_box | D37: ASSUMPTION | F37: logistics.yaml | G37: Baled sheet at ~0.6 t/m³ needs ~35 m³ for 21 MT, within a 67 m³ 40ft box, so the road-weight cap still binds | H37: PENDING — as container_payload_mt_40ft | I37: Equal to the 40ft base.
A38: container_payload_mt_40ft_tense | B38: 21 | C38: mt_per_box | D38: ASSUMPTION | F38: logistics.yaml | G38: US road-weight cap binds (see container_payload_mt_40ft) | H38: PENDING — as container_payload_mt_40ft | I38: Equal to the 40ft base.
A39: port_cf_charges_inr_t_nsa | B39: 1600 | C39: inr_per_mt | D39: ASSUMPTION | F39: logistics.yaml | G39: Desk build-up per 20ft box / 25 MT base payload; component magnitudes are desk estimates (no 2022 tariff retrieved — carrier THC PDFs returned 403), not quotes | H39: PENDING — retrieve 2022 Wayback copies of a carrier's India import THC/DO tariff and a JNPT CFS tariff; get a 2022 short-haul (~200 km) 20ft truck rate out of JNPT | I39: Components per 20ft box (INR): destination THC ~9,500; CFS handling + ground rent within free days ~7,500; delivery order + B/L/documentation ~1,000; customs broker (CHA) fees ~3,000; examination, radiation-check and labour ~2,000; inland haulage to the SIM buyer within ~200 km of JNPT ~16,000 (review fix: previously ~52,000 for ~850 km to Rajkot; the short haul is priced above the long haul's per-km rate). Total ~39,000 per box = ~1,560/MT at 25 MT, rounded to 1,600. Range 1,200-2,500/MT. Excludes customs duty, IGST, demurrage and the PSIC fee (psic_cost_usd_per_box, added separately in CONTRACTS §5 for this non-safe-origin lane).
A40: port_cf_charges_inr_t_mun | B40: 2650 | C40: inr_per_mt | D40: ASSUMPTION | F40: logistics.yaml | G40: Desk build-up per 40ft box / 21 MT; component magnitudes are desk estimates (no 2022 tariff retrieved — carrier THC PDFs returned 403), not quotes | H40: PENDING — retrieve 2022 Wayback copies of a carrier's Mundra import THC/DO tariff and an Adani Mundra CFS tariff; get a 2022 Mundra->Rajkot 40ft trailer rate | I40: Components per 40ft box (INR): destination THC ~14,500; CFS handling + ground rent within free days ~10,000; DO + documentation ~1,000; CHA ~3,500; examination, radiation-check and labour ~2,500; inland haulage Mundra -> Rajkot (~240 km) ~24,000. Total ~55,500 per box = ~2,650/MT at 21 MT. Range 1,800-3,800/MT. The per-tonne port cost is higher than NSA (fewer tonnes per box) but haulage is far shorter.
A41: psic_required_uae_origin | B41: TRUE | C41: bool | D41: DIRECT | F41: regulatory.yaml | G41: DGFT Public Notice 46/2015-2020 (14-Jan-2022): exemption limited to the six named safe origins; other origins remain subject to PSIC | H41: PARTIAL — republisher text read; DGFT original not fetched | I41: UAE is not a 'safe country', so Jebel Ali cargo into Nhava Sheva (JEA_NSA) needs a Pre-Shipment Inspection Certificate from a DGFT-recognised inspection agency (list at https://www.dgft.gov.in/CP/?opt=psia) even though JNPT is a designated port. Operational consequence: add PSIC cost and lead time to every Gulf fixture.
A42: psic_required_safe_origin_designated_port | B42: FALSE | C42: bool | D42: DIRECT | F42: regulatory.yaml | G42: DGFT Public Notice 46/2015-2020 (14-Jan-2022), para 2.54(d)(v)(iv) as amended (see import_policy_hs7602) | H42: PARTIAL — republisher text read (worldtradescanner, bizsolindia); DGFT original not fetched | I42: Metallic scrap from USA, UK, Canada, New Zealand, Australia and the EU needs no PSIC when cleared at one of ten ports (Chennai, Tuticorin, Kandla, JNPT, Mumbai, Krishnapatnam, Mundra, Kattupalli, Hazira, Kamarajar), provided it carries a supplier/scrap-yard certificate of no radioactive material/explosives and passes portal-monitor radiation and container-scanner checks at the port. => the USEC_MUN lane (US origin into Mundra) needs no PSIC.
A43: finance_days_jea_nsa | B43: 40 | C43: days | D43: ASSUMPTION | F43: logistics.yaml | G43: Desk construction from components: LC-at-sight payment, transit_days_jea_nsa, clearance_delivery_days, 30-day domestic buyer credit | H43: PENDING — reconcile with the payment terms P2 assigns in config/trades.yaml (LC sight vs usance; buyer advance vs 30d credit) | I43: DEFINITION: days the desk's own INR working capital is tied up per tonne, from the day it pays the supplier to the day it receives the domestic buyer's payment. Timeline from B/L date: supplier paid under a sight LC on document presentation ~day 7 (goods already arrived after 5 days sailing; release by telex/LOI), BoE and duty ~day 8, out-of-charge + delivery ~day 17 (clearance_delivery_days after arrival, discharge queue included), buyer pays 30 days after delivery ~day 47 => 47 - 7 = 40 days. Applied in CONTRACTS §5 to (goods value at market FX + duties) for simplicity, which slightly overstates duty financing (duty is paid ~1 day after cash-out here). P1 must NOT add buyer-credit days again. A 60-90d usance LC would shorten this by the usance period (usance interest is then priced separately).
A44: finance_days_usec_mun | B44: 73 | C44: days | D44: ASSUMPTION | F44: logistics.yaml | G44: Desk construction from components: LC-at-sight payment, transit_days_usec_mun, clearance_delivery_days, 30-day domestic buyer credit | H44: PENDING — reconcile with the payment terms P2 assigns in config/trades.yaml (LC sight vs usance; buyer advance vs 30d credit) | I44: Same DEFINITION as finance_days_jea_nsa. Timeline from B/L date: sight LC paid ~day 7, arrival day 40, BoE and duty ~day 41, delivery ~day 50, buyer pays ~day 80 => 80 - 7 = 73 days. Here duty is paid ~34 days after cash-out, so applying 73 days to duties overstates finance cost on duties by ~34 days' interest (~INR 50/MT at 2.75% effective duty on ~INR 2 lakh/MT assessable value); accepted for formula simplicity and noted for P1.
A45: moisture_frac_zorba | B45: 0.01 | C45: frac_of_gross_weight | D45: ASSUMPTION | F45: scrap_grades.yaml | G45: ISRI 2022 Zorba spec sets metal content by agreement and requires the lot free of radioactive material, dross and ash, but sets no moisture limit; the sister fragmentizer grades require material to be 'dry' (Twitch/Tweak). Level = desk SPA franchise (standard_moisture_franchise_frac) | H45: N/A — assumption; SPA-driven | I45: Shredded Zorba from wet media separation can arrive at 1–3% moisture; the SPA deducts weight above the 1% franchise, so the desk pays for at most ~1%.
...

Sheet Market_Daily
A1: ACADEMIC SIMULATION — not actual trades
A2: Market_Daily — LME trading-day panel (data/processed/market_daily.csv)
A3: DIRECT: LME cash / 3M / spread / stock (Westmetall). PROXY: usdinr (ECB cross), the 3-month rates, the MCX columns (duty-paid import parity). ASSUMPTION: freight levels, wc_rate_inr_pa. The row directly above the headers carries each column's flag, read from data/processed/series_provenance.csv and the register.
A4: DIRECT | B4: DIRECT | C4: DIRECT | D4: DIRECT | E4: DIRECT | F4: PROXY | G4: PROXY | H4: PROXY | I4: PROXY | J4: PROXY | K4: DIRECT | L4: PROXY | M4: PROXY | N4: PROXY | O4: ASSUMPTION | P4: ASSUMPTION | Q4: ASSUMPTION | R4: ASSUMPTION | S4: — | T4: — | U4: ASSUMPTION | V4: DIRECT | W4: — | X4: ASSUMPTION | Y4: ASSUMPTION | Z4: ASSUMPTION | AA4: ASSUMPTION | AB4: PROXY | AC4: PROXY | AD4: PROXY | AE4: PROXY | AF4: ASSUMPTION | AG4: PROXY | AH4: ASSUMPTION
A5: date | B5: lme_cash_usd_t | C5: lme_3m_usd_t | D5: lme_cash_3m_spread_usd_t | E5: lme_stock_mt | F5: usdinr | G5: usdinr_fwd_1m | H5: usdinr_fwd_3m | I5: inr_rate_3m_pa | J5: usd_rate_3m_pa | K5: rbi_repo_pa | L5: mcx_al_spot_inr_kg | M5: mcx_al_m1_inr_kg | N5: mcx_al_m2_inr_kg | O5: freight_jea_nsa_usd_t | P5: freight_usec_mun_usd_t | Q5: mcx_m1_expiry | R5: mcx_m2_expiry | S5: mcx_m1_month | T5: mcx_m2_month | U5: wc_rate_inr_pa | V5: customs_usdinr_import | W5: customs_fx_src | X5: grade_factor_zorba | Y5: grade_factor_taint_tabor | Z5: grade_factor_tense | AA5: grade_factor_mix_pit | AB5: mcx_theo_m1_inr_kg | AC5: mcx_basis_m1_inr_kg | AD5: mcx_src | AE5: usdinr_src | AF5: freight_src | AG5: usdinr_filled | AH5: freight_filled
A6: 44565 | B6: 2815.5 | C6: 2823 | D6: -7.5 | E6: 934375 | F6: 74.6569 | G6: 74.882 | H6: 75.3103 | I6: 0.0363 | J6: 0.000789 | K6: 0.04 | L6: 227.5377 | M6: 228.1487 | N6: 228.7823 | O6: 24.07 | P6: 106.72 | Q6: 44592 | R6: 44620 | S6: =YEAR($Q6)*100+MONTH($Q6) | T6: =YEAR($R6)*100+MONTH($R6) | U6: =IF($A6<=INDEX(pdates_wc_rate_inr_pa,1),INDEX(pvals_wc_rate_inr_pa,1),INDEX(pvals_wc_rate_inr_pa,MATCH($A6,pdates_wc_rate_inr_pa,1))) | V6: =IF(AND($A6>=customs_fx_first,$A6<=customs_fx_last+customs_fx_notification_validity_days),IF($A6<=INDEX(pdates_customs_usdinr_import,1),INDEX(pvals_customs_usdinr_import,1),INDEX(pvals_customs_usdinr_import,MATCH($A6,pdates_customs_usdinr_import,1))),$F6*(1+customs_fx_markup_frac)) | W6: =IF(AND($A6>=customs_fx_first,$A6<=customs_fx_last+customs_fx_notification_validity_days),"CBIC_NOTIFIED","MARKUP_FALLBACK") | X6: =IF($A6<=INDEX(pdates_grade_factor_zorba,1),INDEX(pvals_grade_factor_zorba,1),IF($A6>=INDEX(pdates_grade_factor_zorba,10),INDEX(pvals_grade_factor_zorba,10),INDEX(pvals_grade_factor_zorba,MATCH($A6,pdates_grade_factor_zorba,1))+($A6-INDEX(pdates_grade_factor_zorba,MATCH($A6,pdates_grade_factor_zorba,1)))/(INDEX(pdates_grade_factor_zorba,MATCH($A6,pdates_grade_factor_zorba,1)+1)-INDEX(pdates_grade_factor_zorba,MATCH($A6,pdates_grade_factor_zorba,1)))*(INDEX(pvals_grade_factor_zorba,MATCH($A6,pdates_grade_factor_zorba,1)+1)-INDEX(pvals_grade_factor_zorba,MATCH($A6,pdates_grade_factor_zorba,1))))) | Y6: =IF($A6<=INDEX(pdates_grade_factor_taint_tabor,1),INDEX(pvals_grade_factor_taint_tabor,1),IF($A6>=INDEX(pdates_grade_factor_taint_tabor,10),INDEX(pvals_grade_factor_taint_tabor,10),INDEX(pvals_grade_factor_taint_tabor,MATCH($A6,pdates_grade_factor_taint_tabor,1))+($A6-INDEX(pdates_grade_factor_taint_tabor,MATCH($A6,pdates_grade_factor_taint_tabor,1)))/(INDEX(pdates_grade_factor_taint_tabor,MATCH($A6,pdates_grade_factor_taint_tabor,1)+1)-INDEX(pdates_grade_factor_taint_tabor,MATCH($A6,pdates_grade_factor_taint_tabor,1)))*(INDEX(pvals_grade_factor_taint_tabor,MATCH($A6,pdates_grade_factor_taint_tabor,1)+1)-INDEX(pvals_grade_factor_taint_tabor,MATCH($A6,pdates_grade_factor_taint_tabor,1))))) | Z6: =IF($A6<=INDEX(pdates_grade_factor_tense,1),INDEX(pvals_grade_factor_tense,1),IF($A6>=INDEX(pdates_grade_factor_tense,10),INDEX(pvals_grade_factor_tense,10),INDEX(pvals_grade_factor_tense,MATCH($A6,pdates_grade_factor_tense,1))+($A6-INDEX(pdates_grade_factor_tense,MATCH($A6,pdates_grade_factor_tense,1)))/(INDEX(pdates_grade_factor_tense,MATCH($A6,pdates_grade_factor_tense,1)+1)-INDEX(pdates_grade_factor_tense,MATCH($A6,pdates_grade_factor_tense,1)))*(INDEX(pvals_grade_factor_tense,MATCH($A6,pdates_grade_factor_tense,1)+1)-INDEX(pvals_grade_factor_tense,MATCH($A6,pdates_grade_factor_tense,1))))) | AA6: =IF($A6<=INDEX(pdates_grade_factor_mix_pit,1),INDEX(pvals_grade_factor_mix_pit,1),IF($A6>=INDEX(pdates_grade_factor_mix_pit,10),INDEX(pvals_grade_factor_mix_pit,10),INDEX(pvals_grade_factor_mix_pit,MATCH($A6,pdates_grade_factor_mix_pit,1))+($A6-INDEX(pdates_grade_factor_mix_pit,MATCH($A6,pdates_grade_factor_mix_pit,1)))/(INDEX(pdates_grade_factor_mix_pit,MATCH($A6,pdates_grade_factor_mix_pit,1)+1)-INDEX(pdates_grade_factor_mix_pit,MATCH($A6,pdates_grade_factor_mix_pit,1)))*(INDEX(pvals_grade_factor_mix_pit,MATCH($A6,pdates_grade_factor_mix_pit,1)+1)-INDEX(pvals_grade_factor_mix_pit,MATCH($A6,pdates_grade_factor_mix_pit,1))))) | AB6: =($B6*$F6/kg_per_mt*(1+bcd_primary_al_hs7601*(1+sws_rate_on_bcd))+mcx_domestic_premium_inr_kg)*(1+$I6*MAX(0,$Q6-$A6)/day_count_inr) | AC6: =$M6-$AB6 | AD6: PROXY_IMPORT_PARITY | AE6: ECB_CROSS | AF6: WCI_DERIVED|USEC:EXTRAP_PRE|JEA:ASSUMPTION | AG6: FALSE | AH6: TRUE
A7: 44566 | B7: 2866 | C7: 2885 | D7: -19 | E7: 926800 | F7: 74.3537 | G7: 74.5773 | H7: 75.0026 | I7: 0.0363 | J7: 0.000888 | K7: 0.04 | L7: 230.6783 | M7: 231.2747 | N7: 231.9171 | O7: 24.07 | P7: 106.72 | Q7: 44592 | R7: 44620 | S7: =YEAR($Q7)*100+MONTH($Q7) | T7: =YEAR($R7)*100+MONTH($R7) | U7: =IF($A7<=INDEX(pdates_wc_rate_inr_pa,1),INDEX(pvals_wc_rate_inr_pa,1),INDEX(pvals_wc_rate_inr_pa,MATCH($A7,pdates_wc_rate_inr_pa,1))) | V7: =IF(AND($A7>=customs_fx_first,$A7<=customs_fx_last+customs_fx_notification_validity_days),IF($A7<=INDEX(pdates_customs_usdinr_import,1),INDEX(pvals_customs_usdinr_import,1),INDEX(pvals_customs_usdinr_import,MATCH($A7,pdates_customs_usdinr_import,1))),$F7*(1+customs_fx_markup_frac)) | W7: =IF(AND($A7>=customs_fx_first,$A7<=customs_fx_last+customs_fx_notification_validity_days),"CBIC_NOTIFIED","MARKUP_FALLBACK") | X7: =IF($A7<=INDEX(pdates_grade_factor_zorba,1),INDEX(pvals_grade_factor_zorba,1),IF($A7>=INDEX(pdates_grade_factor_zorba,10),INDEX(pvals_grade_factor_zorba,10),INDEX(pvals_grade_factor_zorba,MATCH($A7,pdates_grade_factor_zorba,1))+($A7-INDEX(pdates_grade_factor_zorba,MATCH($A7,pdates_grade_factor_zorba,1)))/(INDEX(pdates_grade_factor_zorba,MATCH($A7,pdates_grade_factor_zorba,1)+1)-INDEX(pdates_grade_factor_zorba,MATCH($A7,pdates_grade_factor_zorba,1)))*(INDEX(pvals_grade_factor_zorba,MATCH($A7,pdates_grade_factor_zorba,1)+1)-INDEX(pvals_grade_factor_zorba,MATCH($A7,pdates_grade_factor_zorba,1))))) | Y7: =IF($A7<=INDEX(pdates_grade_factor_taint_tabor,1),INDEX(pvals_grade_factor_taint_tabor,1),IF($A7>=INDEX(pdates_grade_factor_taint_tabor,10),INDEX(pvals_grade_factor_taint_tabor,10),INDEX(pvals_grade_factor_taint_tabor,MATCH($A7,pdates_grade_factor_taint_tabor,1))+($A7-INDEX(pdates_grade_factor_taint_tabor,MATCH($A7,pdates_grade_factor_taint_tabor,1)))/(INDEX(pdates_grade_factor_taint_tabor,MATCH($A7,pdates_grade_factor_taint_tabor,1)+1)-INDEX(pdates_grade_factor_taint_tabor,MATCH($A7,pdates_grade_factor_taint_tabor,1)))*(INDEX(pvals_grade_factor_taint_tabor,MATCH($A7,pdates_grade_factor_taint_tabor,1)+1)-INDEX(pvals_grade_factor_taint_tabor,MATCH($A7,pdates_grade_factor_taint_tabor,1))))) | Z7: =IF($A7<=INDEX(pdates_grade_factor_tense,1),INDEX(pvals_grade_factor_tense,1),IF($A7>=INDEX(pdates_grade_factor_tense,10),INDEX(pvals_grade_factor_tense,10),INDEX(pvals_grade_factor_tense,MATCH($A7,pdates_grade_factor_tense,1))+($A7-INDEX(pdates_grade_factor_tense,MATCH($A7,pdates_grade_factor_tense,1)))/(INDEX(pdates_grade_factor_tense,MATCH($A7,pdates_grade_factor_tense,1)+1)-INDEX(pdates_grade_factor_tense,MATCH($A7,pdates_grade_factor_tense,1)))*(INDEX(pvals_grade_factor_tense,MATCH($A7,pdates_grade_factor_tense,1)+1)-INDEX(pvals_grade_factor_tense,MATCH($A7,pdates_grade_factor_tense,1))))) | AA7: =IF($A7<=INDEX(pdates_grade_factor_mix_pit,1),INDEX(pvals_grade_factor_mix_pit,1),IF($A7>=INDEX(pdates_grade_factor_mix_pit,10),INDEX(pvals_grade_factor_mix_pit,10),INDEX(pvals_grade_factor_mix_pit,MATCH($A7,pdates_grade_factor_mix_pit,1))+($A7-INDEX(pdates_grade_factor_mix_pit,MATCH($A7,pdates_grade_factor_mix_pit,1)))/(INDEX(pdates_grade_factor_mix_pit,MATCH($A7,pdates_grade_factor_mix_pit,1)+1)-INDEX(pdates_grade_factor_mix_pit,MATCH($A7,pdates_grade_factor_mix_pit,1)))*(INDEX(pvals_grade_factor_mix_pit,MATCH($A7,pdates_grade_factor_mix_pit,1)+1)-INDEX(pvals_grade_factor_mix_pit,MATCH($A7,pdates_grade_factor_mix_pit,1))))) | AB7: =($B7*$F7/kg_per_mt*(1+bcd_primary_al_hs7601*(1+sws_rate_on_bcd))+mcx_domestic_premium_inr_kg)*(1+$I7*MAX(0,$Q7-$A7)/day_count_inr) | AC7: =$M7-$AB7 | AD7: PROXY_IMPORT_PARITY | AE7: ECB_CROSS | AF7: WCI_DERIVED|USEC:EXTRAP_PRE|JEA:ASSUMPTION | AG7: FALSE | AH7: TRUE
A8: 44567 | B8: 2912.5 | C8: 2923.5 | D8: -11 | E8: 921400 | F8: 74.4565 | G8: 74.6797 | H8: 75.1044 | I8: 0.0363 | J8: 0.000986 | K8: 0.04 | L8: 234.7451 | M8: 235.3287 | N8: 235.9824 | O8: 24.33 | P8: 107.9 | Q8: 44592 | R8: 44620 | S8: =YEAR($Q8)*100+MONTH($Q8) | T8: =YEAR($R8)*100+MONTH($R8) | U8: =IF($A8<=INDEX(pdates_wc_rate_inr_pa,1),INDEX(pvals_wc_rate_inr_pa,1),INDEX(pvals_wc_rate_inr_pa,MATCH($A8,pdates_wc_rate_inr_pa,1))) | V8: =IF(AND($A8>=customs_fx_first,$A8<=customs_fx_last+customs_fx_notification_validity_days),IF($A8<=INDEX(pdates_customs_usdinr_import,1),INDEX(pvals_customs_usdinr_import,1),INDEX(pvals_customs_usdinr_import,MATCH($A8,pdates_customs_usdinr_import,1))),$F8*(1+customs_fx_markup_frac)) | W8: =IF(AND($A8>=customs_fx_first,$A8<=customs_fx_last+customs_fx_notification_validity_days),"CBIC_NOTIFIED","MARKUP_FALLBACK") | X8: =IF($A8<=INDEX(pdates_grade_factor_zorba,1),INDEX(pvals_grade_factor_zorba,1),IF($A8>=INDEX(pdates_grade_factor_zorba,10),INDEX(pvals_grade_factor_zorba,10),INDEX(pvals_grade_factor_zorba,MATCH($A8,pdates_grade_factor_zorba,1))+($A8-INDEX(pdates_grade_factor_zorba,MATCH($A8,pdates_grade_factor_zorba,1)))/(INDEX(pdates_grade_factor_zorba,MATCH($A8,pdates_grade_factor_zorba,1)+1)-INDEX(pdates_grade_factor_zorba,MATCH($A8,pdates_grade_factor_zorba,1)))*(INDEX(pvals_grade_factor_zorba,MATCH($A8,pdates_grade_factor_zorba,1)+1)-INDEX(pvals_grade_factor_zorba,MATCH($A8,pdates_grade_factor_zorba,1))))) | Y8: =IF($A8<=INDEX(pdates_grade_factor_taint_tabor,1),INDEX(pvals_grade_factor_taint_tabor,1),IF($A8>=INDEX(pdates_grade_factor_taint_tabor,10),INDEX(pvals_grade_factor_taint_tabor,10),INDEX(pvals_grade_factor_taint_tabor,MATCH($A8,pdates_grade_factor_taint_tabor,1))+($A8-INDEX(pdates_grade_factor_taint_tabor,MATCH($A8,pdates_grade_factor_taint_tabor,1)))/(INDEX(pdates_grade_factor_taint_tabor,MATCH($A8,pdates_grade_factor_taint_tabor,1)+1)-INDEX(pdates_grade_factor_taint_tabor,MATCH($A8,pdates_grade_factor_taint_tabor,1)))*(INDEX(pvals_grade_factor_taint_tabor,MATCH($A8,pdates_grade_factor_taint_tabor,1)+1)-INDEX(pvals_grade_factor_taint_tabor,MATCH($A8,pdates_grade_factor_taint_tabor,1))))) | Z8: =IF($A8<=INDEX(pdates_grade_factor_tense,1),INDEX(pvals_grade_factor_tense,1),IF($A8>=INDEX(pdates_grade_factor_tense,10),INDEX(pvals_grade_factor_tense,10),INDEX(pvals_grade_factor_tense,MATCH($A8,pdates_grade_factor_tense,1))+($A8-INDEX(pdates_grade_factor_tense,MATCH($A8,pdates_grade_factor_tense,1)))/(INDEX(pdates_grade_factor_tense,MATCH($A8,pdates_grade_factor_tense,1)+1)-INDEX(pdates_grade_factor_tense,MATCH($A8,pdates_grade_factor_tense,1)))*(INDEX(pvals_grade_factor_tense,MATCH($A8,pdates_grade_factor_tense,1)+1)-INDEX(pvals_grade_factor_tense,MATCH($A8,pdates_grade_factor_tense,1))))) | AA8: =IF($A8<=INDEX(pdates_grade_factor_mix_pit,1),INDEX(pvals_grade_factor_mix_pit,1),IF($A8>=INDEX(pdates_grade_factor_mix_pit,10),INDEX(pvals_grade_factor_mix_pit,10),INDEX(pvals_grade_factor_mix_pit,MATCH($A8,pdates_grade_factor_mix_pit,1))+($A8-INDEX(pdates_grade_factor_mix_pit,MATCH($A8,pdates_grade_factor_mix_pit,1)))/(INDEX(pdates_grade_factor_mix_pit,MATCH($A8,pdates_grade_factor_mix_pit,1)+1)-INDEX(pdates_grade_factor_mix_pit,MATCH($A8,pdates_grade_factor_mix_pit,1)))*(INDEX(pvals_grade_factor_mix_pit,MATCH($A8,pdates_grade_factor_mix_pit,1)+1)-INDEX(pvals_grade_factor_mix_pit,MATCH($A8,pdates_grade_factor_mix_pit,1))))) | AB8: =($B8*$F8/kg_per_mt*(1+bcd_primary_al_hs7601*(1+sws_rate_on_bcd))+mcx_domestic_premium_inr_kg)*(1+$I8*MAX(0,$Q8-$A8)/day_count_inr) | AC8: =$M8-$AB8 | AD8: PROXY_IMPORT_PARITY | AE8: ECB_CROSS | AF8: WCI_REPORTED|USEC:EXTRAP_PRE|JEA:ASSUMPTION | AG8: FALSE | AH8: FALSE
A9: 44568 | B9: 2919.5 | C9: 2932 | D9: -12.5 | E9: 916875 | F9: 74.33 | G9: 74.5528 | H9: 74.9768 | I9: 0.0363 | J9: 0.000986 | K9: 0.04 | L9: 234.9095 | M9: 235.4702 | N9: 236.1243 | O9: 24.33 | P9: 107.9 | Q9: 44592 | R9: 44620 | S9: =YEAR($Q9)*100+MONTH($Q9) | T9: =YEAR($R9)*100+MONTH($R9) | U9: =IF($A9<=INDEX(pdates_wc_rate_inr_pa,1),INDEX(pvals_wc_rate_inr_pa,1),INDEX(pvals_wc_rate_inr_pa,MATCH($A9,pdates_wc_rate_inr_pa,1))) | V9: =IF(AND($A9>=customs_fx_first,$A9<=customs_fx_last+customs_fx_notification_validity_days),IF($A9<=INDEX(pdates_customs_usdinr_import,1),INDEX(pvals_customs_usdinr_import,1),INDEX(pvals_customs_usdinr_import,MATCH($A9,pdates_customs_usdinr_import,1))),$F9*(1+customs_fx_markup_frac)) | W9: =IF(AND($A9>=customs_fx_first,$A9<=customs_fx_last+customs_fx_notification_validity_days),"CBIC_NOTIFIED","MARKUP_FALLBACK") | X9: =IF($A9<=INDEX(pdates_grade_factor_zorba,1),INDEX(pvals_grade_factor_zorba,1),IF($A9>=INDEX(pdates_grade_factor_zorba,10),INDEX(pvals_grade_factor_zorba,10),INDEX(pvals_grade_factor_zorba,MATCH($A9,pdates_grade_factor_zorba,1))+($A9-INDEX(pdates_grade_factor_zorba,MATCH($A9,pdates_grade_factor_zorba,1)))/(INDEX(pdates_grade_factor_zorba,MATCH($A9,pdates_grade_factor_zorba,1)+1)-INDEX(pdates_grade_factor_zorba,MATCH($A9,pdates_grade_factor_zorba,1)))*(INDEX(pvals_grade_factor_zorba,MATCH($A9,pdates_grade_factor_zorba,1)+1)-INDEX(pvals_grade_factor_zorba,MATCH($A9,pdates_grade_factor_zorba,1))))) | Y9: =IF($A9<=INDEX(pdates_grade_factor_taint_tabor,1),INDEX(pvals_grade_factor_taint_tabor,1),IF($A9>=INDEX(pdates_grade_factor_taint_tabor,10),INDEX(pvals_grade_factor_taint_tabor,10),INDEX(pvals_grade_factor_taint_tabor,MATCH($A9,pdates_grade_factor_taint_tabor,1))+($A9-INDEX(pdates_grade_factor_taint_tabor,MATCH($A9,pdates_grade_factor_taint_tabor,1)))/(INDEX(pdates_grade_factor_taint_tabor,MATCH($A9,pdates_grade_factor_taint_tabor,1)+1)-INDEX(pdates_grade_factor_taint_tabor,MATCH($A9,pdates_grade_factor_taint_tabor,1)))*(INDEX(pvals_grade_factor_taint_tabor,MATCH($A9,pdates_grade_factor_taint_tabor,1)+1)-INDEX(pvals_grade_factor_taint_tabor,MATCH($A9,pdates_grade_factor_taint_tabor,1))))) | Z9: =IF($A9<=INDEX(pdates_grade_factor_tense,1),INDEX(pvals_grade_factor_tense,1),IF($A9>=INDEX(pdates_grade_factor_tense,10),INDEX(pvals_grade_factor_tense,10),INDEX(pvals_grade_factor_tense,MATCH($A9,pdates_grade_factor_tense,1))+($A9-INDEX(pdates_grade_factor_tense,MATCH($A9,pdates_grade_factor_tense,1)))/(INDEX(pdates_grade_factor_tense,MATCH($A9,pdates_grade_factor_tense,1)+1)-INDEX(pdates_grade_factor_tense,MATCH($A9,pdates_grade_factor_tense,1)))*(INDEX(pvals_grade_factor_tense,MATCH($A9,pdates_grade_factor_tense,1)+1)-INDEX(pvals_grade_factor_tense,MATCH($A9,pdates_grade_factor_tense,1))))) | AA9: =IF($A9<=INDEX(pdates_grade_factor_mix_pit,1),INDEX(pvals_grade_factor_mix_pit,1),IF($A9>=INDEX(pdates_grade_factor_mix_pit,10),INDEX(pvals_grade_factor_mix_pit,10),INDEX(pvals_grade_factor_mix_pit,MATCH($A9,pdates_grade_factor_mix_pit,1))+($A9-INDEX(pdates_grade_factor_mix_pit,MATCH($A9,pdates_grade_factor_mix_pit,1)))/(INDEX(pdates_grade_factor_mix_pit,MATCH($A9,pdates_grade_factor_mix_pit,1)+1)-INDEX(pdates_grade_factor_mix_pit,MATCH($A9,pdates_grade_factor_mix_pit,1)))*(INDEX(pvals_grade_factor_mix_pit,MATCH($A9,pdates_grade_factor_mix_pit,1)+1)-INDEX(pvals_grade_factor_mix_pit,MATCH($A9,pdates_grade_factor_mix_pit,1))))) | AB9: =($B9*$F9/kg_per_mt*(1+bcd_primary_al_hs7601*(1+sws_rate_on_bcd))+mcx_domestic_premium_inr_kg)*(1+$I9*MAX(0,$Q9-$A9)/day_count_inr) | AC9: =$M9-$AB9 | AD9: PROXY_IMPORT_PARITY | AE9: ECB_CROSS | AF9: WCI_REPORTED|USEC:EXTRAP_PRE|JEA:ASSUMPTION | AG9: FALSE | AH9: TRUE
